<?xml version="1.0" ?>
<!-- =================================================================================== -->
<!-- |    This document was autogenerated by xacro from gazebo_2f.xacro                | -->
<!-- |    EDITING THIS FILE BY HAND IS NOT RECOMMENDED                                 | -->
<!-- =================================================================================== -->
<robot name="abb_gripper">
  <!-- Conversion were obtained from http://www.e-paint.co.uk/Lab_values.asp
       unless otherwise stated. -->
  <!-- link list -->
  <link name="base_link">
    <collision name="collision">
      <geometry>
        <mesh filename="package://abb_irb4600_description/meshes/irb4600/collision/base_link.stl"/>
      </geometry>
      <material name="">
        <color rgba="0.9254902 0.9254902 0.9058824 1"/>
      </material>
    </collision>
    <inertial>
      <mass value="23.085357"/>
      <origin rpy="0.0 0.0 0.0" xyz="0.007579 0.000017 0.180670"/>
      <inertia ixx="0.343576" ixy="-0.000062" ixz="-0.002079" iyy="0.336217" iyz="-0.000014" izz="0.334050"/>
    </inertial>
    <visual name="visual">
      <geometry>
        <mesh filename="package://abb_irb4600_description/meshes/irb4600/visual/base_link.dae"/>
      </geometry>
      <material name="">
        <color rgba="0.9254902 0.9254902 0.9058824 1"/>
      </material>
      <material name="yellow">
        <color rgba="1 1 0 1"/>
      </material>
    </visual>
  </link>
  <link name="link_1">
    <collision name="collision">
      <geometry>
        <mesh filename="package://abb_irb4600_description/meshes/irb4600/collision/link_1.stl"/>
      </geometry>
      <material name="">
        <color rgba="0.9254902 0.9254902 0.9058824 1"/>
      </material>
    </collision>
    <inertial>
      <mass value="45.357763"/>
      <origin rpy="0.0 0.0 0.0" xyz="0.085479 -0.002547 -0.040488"/>
      <inertia ixx="0.839141" ixy="0.022637" ixz="0.162457" iyy="1.030146" iyz="0.027416" izz="1.064698"/>
    </inertial>
    <visual name="visual">
      <geometry>
        <mesh filename="package://abb_irb4600_description/meshes/irb4600/visual/link_1.dae"/>
      </geometry>
      <material name="">
        <color rgba="0.9254902 0.9254902 0.9058824 1"/>
      </material>
      <material name="yellow"/>
    </visual>
  </link>
  <link name="link_2">
    <collision name="collision">
      <geometry>
        <mesh filename="package://abb_irb4600_description/meshes/irb4600_20_250/collision/link_2.stl"/>
      </geometry>
      <material name="">
        <color rgba="0.9254902 0.9254902 0.9058824 1"/>
      </material>
    </collision>
    <inertial>
      <mass value="51.266495"/>
      <origin rpy="0.0 0.0 0.0" xyz="-0.000002 0.264164 0.347704"/>
      <inertia ixx="5.272800" ixy="0.000010" ixz="0.000017" iyy="5.536809" iyz="-0.008261" izz="0.486191"/>
    </inertial>
    <visual name="visual">
      <geometry>
        <mesh filename="package://abb_irb4600_description/meshes/irb4600_20_250/visual/link_2.dae"/>
      </geometry>
      <material name="">
        <color rgba="0.9254902 0.9254902 0.9058824 1"/>
      </material>
      <material name="yellow"/>
    </visual>
  </link>
  <link name="link_3">
    <collision name="collision">
      <geometry>
        <mesh filename="package://abb_irb4600_description/meshes/irb4600_20_250/collision/link_3.stl"/>
      </geometry>
      <material name="">
        <color rgba="0.9254902 0.9254902 0.9058824 1"/>
      </material>
    </collision>
    <inertial>
      <mass value="19.754401"/>
      <origin rpy="0.0 0.0 0.0" xyz="-0.000255 0.016478 -0.003819"/>
      <inertia ixx="0.249388" ixy="-0.004901" ixz="0.004825" iyy="0.211780" iyz="0.000574" izz="0.238488"/>
    </inertial>
    <visual name="visual">
      <geometry>
        <mesh filename="package://abb_irb4600_description/meshes/irb4600_20_250/visual/link_3.dae"/>
      </geometry>
      <material name="">
        <color rgba="0.9254902 0.9254902 0.9058824 1"/>
      </material>
      <material name="yellow"/>
    </visual>
  </link>
  <link name="link_4">
    <collision name="collision">
      <geometry>
        <mesh filename="package://abb_irb4600_description/meshes/irb4600_20_250/collision/link_4.stl"/>
      </geometry>
      <material name="">
        <color rgba="0.9254902 0.9254902 0.9058824 1"/>
      </material>
    </collision>
    <inertial>
      <mass value="15.287896"/>
      <origin rpy="0.0 0.0 0.0" xyz="-0.015515 0.000164 0.340348"/>
      <inertia ixx="0.331593" ixy="0.000055" ixz="-0.010688" iyy="0.320895" iyz="0.000058" izz="0.086557"/>
    </inertial>
    <visual name="visual">
      <geometry>
        <mesh filename="package://abb_irb4600_description/meshes/irb4600_20_250/visual/link_4.dae"/>
      </geometry>
      <material name="">
        <color rgba="0.9254902 0.9254902 0.9058824 1"/>
      </material>
      <material name="yellow"/>
    </visual>
  </link>
  <link name="link_5">
    <collision name="collision">
      <geometry>
        <mesh filename="package://abb_irb4600_description/meshes/irb4600_20_250/collision/link_5.stl"/>
      </geometry>
      <material name="">
        <color rgba="0.9254902 0.9254902 0.9058824 1"/>
      </material>
    </collision>
    <inertial>
      <mass value="0.548088"/>
      <origin rpy="0.0 0.0 0.0" xyz="0.000000 -0.000347 0.023671"/>
      <inertia ixx="0.000876" ixy="0.000000" ixz="0.000000" iyy="0.000889" iyz="0.000005" izz="0.000412"/>
    </inertial>
    <visual name="visual">
      <geometry>
        <mesh filename="package://abb_irb4600_description/meshes/irb4600_20_250/visual/link_5.dae"/>
      </geometry>
      <material name="">
        <color rgba="0.9254902 0.9254902 0.9058824 1"/>
      </material>
      <material name="yellow"/>
    </visual>
  </link>
  <link name="link_6">
    <collision name="collision">
      <geometry>
        <mesh filename="package://abb_irb4600_description/meshes/irb4600_20_250/collision/link_6.stl"/>
      </geometry>
      <material name="">
        <color rgba="0.9254902 0.9254902 0.9058824 1"/>
      </material>
    </collision>
    <inertial>
      <mass value="0.038484"/>
      <origin rpy="0.0 0.0 0.0" xyz="-0.000245 0.000000 -0.007626"/>
      <inertia ixx="0.000011" ixy="0.000000" ixz="0.000000" iyy="0.000011" iyz="0.000000" izz="0.000021"/>
    </inertial>
    <visual name="visual">
      <geometry>
        <mesh filename="package://abb_irb4600_description/meshes/irb4600_20_250/visual/link_6.dae"/>
      </geometry>
      <material name="">
        <color rgba="0.9254902 0.9254902 0.9058824 1"/>
      </material>
      <material name="yellow"/>
    </visual>
  </link>
  <!-- end of link list -->
  <!-- joint list -->
  <joint name="joint_1" type="revolute">
    <origin rpy="0 0 0" xyz="0 0 0.495"/>
    <axis xyz="0 0 1"/>
    <parent link="base_link"/>
    <child link="link_1"/>
    <limit effort="692" lower="-3.141592653589793" upper="3.141592653589793" velocity="3.0543261909900767"/>
    <dynamics damping="0.0" friction="0.0"/>
  </joint>
  <joint name="joint_2" type="revolute">
    <origin rpy="0 0 0" xyz="0.175 0 0"/>
    <axis xyz="0 1 0"/>
    <parent link="link_1"/>
    <child link="link_2"/>
    <limit effort="574" lower="-1.5707963267948966" upper="2.6179938779914944" velocity="3.0543261909900767"/>
    <dynamics damping="0.0" friction="0.0"/>
  </joint>
  <joint name="joint_3" type="revolute">
    <origin rpy="0 0 0" xyz="0 0 1.095"/>
    <axis xyz="0 1 0"/>
    <parent link="link_2"/>
    <child link="link_3"/>
    <limit effort="242" lower="-3.141592653589793" upper="1.3089969389957472" velocity="3.0543261909900767"/>
    <dynamics damping="0.0" friction="0.0"/>
  </joint>
  <joint name="joint_4" type="revolute">
    <origin rpy="0 0 0" xyz="0 0 0.175"/>
    <axis xyz="1 0 0"/>
    <parent link="link_3"/>
    <child link="link_4"/>
    <limit effort="58" lower="-6.981317007977318" upper="6.981317007977318" velocity="6.283185307179586"/>
    <dynamics damping="0.0" friction="0.0"/>
  </joint>
  <joint name="joint_5" type="revolute">
    <origin rpy="0 0 0" xyz="1.2305 0 0"/>
    <axis xyz="0 1 0"/>
    <parent link="link_4"/>
    <child link="link_5"/>
    <limit effort="29" lower="-2.181661564992912" upper="2.0943951023931953" velocity="6.283185307179586"/>
    <dynamics damping="0.0" friction="0.0"/>
  </joint>
  <joint name="joint_6" type="revolute">
    <origin rpy="0 0 0" xyz="0.085 0 0"/>
    <axis xyz="1 0 0"/>
    <parent link="link_5"/>
    <child link="link_6"/>
    <limit effort="29" lower="-6.981317007977318" upper="6.981317007977318" velocity="8.726646259971648"/>
    <dynamics damping="0.0" friction="0.0"/>
  </joint>
  <!-- end of joint list -->
  <!-- ROS-Industrial 'base' frame: base_link to ABB World Coordinates transform -->
  <link name="base"/>
  <joint name="base_link-base" type="fixed">
    <origin rpy="0 0 0" xyz="0 0 0"/>
    <parent link="base_link"/>
    <child link="base"/>
  </joint>
  <!-- ROS-Industrial 'flange' frame: attachment point for EEF models -->
  <link name="flange"/>
  <joint name="joint_6-flange" type="fixed">
    <origin rpy="0 0 0" xyz="0 0 0"/>
    <parent link="link_6"/>
    <child link="flange"/>
  </joint>
  <!-- ROS-Industrial 'tool0' frame: all-zeros tool frame -->
  <link name="tool0"/>
  <joint name="link_6-tool0" type="fixed">
    <origin rpy="0 1.5707963267948966 0" xyz="0 0 0"/>
    <parent link="flange"/>
    <child link="tool0"/>
  </joint>
  <!-- transmission list -->
  <transmission name="tran1">
    <robotNamespace>/</robotNamespace>
    <type>transmission_interface/SimpleTransmission</type>
    <joint name="joint_1">
      <hardwareInterface>hardware_interface/PositionJointInterface</hardwareInterface>
    </joint>
    <actuator name="motor1">
      <mechanicalReduction>1</mechanicalReduction>
      <hardwareInterface>hardware_interface/PositionJointInterface</hardwareInterface>
    </actuator>
  </transmission>
  <transmission name="tran2">
    <robotNamespace>/</robotNamespace>
    <type>transmission_interface/SimpleTransmission</type>
    <joint name="joint_2">
      <hardwareInterface>hardware_interface/PositionJointInterface</hardwareInterface>
    </joint>
    <actuator name="motor2">
      <mechanicalReduction>1</mechanicalReduction>
      <hardwareInterface>hardware_interface/PositionJointInterface</hardwareInterface>
    </actuator>
  </transmission>
  <transmission name="tran3">
    <robotNamespace>/</robotNamespace>
    <type>transmission_interface/SimpleTransmission</type>
    <joint name="joint_3">
      <hardwareInterface>hardware_interface/PositionJointInterface</hardwareInterface>
    </joint>
    <actuator name="motor3">
      <mechanicalReduction>1</mechanicalReduction>
      <hardwareInterface>hardware_interface/PositionJointInterface</hardwareInterface>
    </actuator>
  </transmission>
  <transmission name="tran4">
    <robotNamespace>/</robotNamespace>
    <type>transmission_interface/SimpleTransmission</type>
    <joint name="joint_4">
      <hardwareInterface>hardware_interface/PositionJointInterface</hardwareInterface>
    </joint>
    <actuator name="motor4">
      <mechanicalReduction>1</mechanicalReduction>
      <hardwareInterface>hardware_interface/PositionJointInterface</hardwareInterface>
    </actuator>
  </transmission>
  <transmission name="tran5">
    <robotNamespace>/</robotNamespace>
    <type>transmission_interface/SimpleTransmission</type>
    <joint name="joint_5">
      <hardwareInterface>hardware_interface/PositionJointInterface</hardwareInterface>
    </joint>
    <actuator name="motor5">
      <mechanicalReduction>1</mechanicalReduction>
      <hardwareInterface>hardware_interface/PositionJointInterface</hardwareInterface>
    </actuator>
  </transmission>
  <transmission name="tran6">
    <robotNamespace>/</robotNamespace>
    <type>transmission_interface/SimpleTransmission</type>
    <joint name="joint_6">
      <hardwareInterface>hardware_interface/PositionJointInterface</hardwareInterface>
    </joint>
    <actuator name="motor6">
      <mechanicalReduction>1</mechanicalReduction>
      <hardwareInterface>hardware_interface/PositionJointInterface</hardwareInterface>
    </actuator>
  </transmission>
  <!-- end of transmission list -->
  <!-- Gazebo-specific link properties -->
  <gazebo reference="base_link">
    <material>Gazebo/Black</material>
    <turnGravityOff>true</turnGravityOff>
  </gazebo>
  <gazebo reference="link_1">
    <material>Gazebo/Orange</material>
    <turnGravityOff>true</turnGravityOff>
  </gazebo>
  <gazebo reference="link_2">
    <material>Gazebo/Orange</material>
    <turnGravityOff>true</turnGravityOff>
  </gazebo>
  <gazebo reference="link_3">
    <material>Gazebo/Orange</material>
    <turnGravityOff>true</turnGravityOff>
  </gazebo>
  <gazebo reference="link_4">
    <material>Gazebo/Orange</material>
    <turnGravityOff>true</turnGravityOff>
  </gazebo>
  <gazebo reference="link_5">
    <material>Gazebo/Grey</material>
    <turnGravityOff>true</turnGravityOff>
  </gazebo>
  <gazebo reference="link_6">
    <material>Gazebo/Grey</material>
    <turnGravityOff>true</turnGravityOff>
  </gazebo>
  <!-- ros_control plugin -->
  <gazebo>
    <plugin filename="libgazebo_ros_control.so" name="gazebo_ros_control">
      <robotNamespace>/</robotNamespace>
      <robotSimType>gazebo_ros_control/DefaultRobotHWSim</robotSimType>
    </plugin>
  </gazebo>
  <!-- Fix robot to Gazebo world -->
  <link name="world"/>
  <joint name="world-base_link-fixed" type="fixed">
    <parent link="world"/>
    <child link="base_link"/>
    <origin rpy="0.0 0.0 0.0" xyz="0.0 0.0 0.0"/>
  </joint>
  <link name="robotiq_arg2f_base_link">
    <inertial>
      <origin rpy="0 0 0" xyz="8.625E-08 -4.6583E-06 0.03145"/>
      <mass value="0.22652"/>
      <inertia ixx="0.00020005" ixy="-4.2442E-10" ixz="-2.9069E-10" iyy="0.00017832" iyz="-3.4402E-08" izz="0.00013478"/>
    </inertial>
    <visual>
      <origin rpy="0 0 0" xyz="0 0 0"/>
      <geometry>
        <mesh filename="package://robotiq_2f_85_description/meshes/collision/robotiq_arg2f_base_link.stl"/>
      </geometry>
      <material name="">
        <color rgba="0.1 0.1 0.1 1"/>
      </material>
    </visual>
    <collision>
      <origin rpy="0 0 0" xyz="0 0 0"/>
      <geometry>
        <mesh filename="package://robotiq_2f_85_description/meshes/collision/robotiq_arg2f_base_link.stl"/>
      </geometry>
    </collision>
  </link>
  <link name="left_outer_knuckle">
    <!--<inertial>
        <origin xyz="-0.000200000000003065 0.0199435877845359 0.0292245259211331" rpy="0 0 0" />
        <mass value="0.00853198276973456" />
        <inertia ixx="2.89328108496468E-06" ixy="-1.57935047237397E-19" ixz="-1.93980378593255E-19" iyy="1.86719750325683E-06" iyz="-1.21858577871576E-06" izz="1.21905238907251E-06" />
        </inertial> -->
    <visual>
      <origin rpy="0 0 0" xyz="0 0 0"/>
      <geometry>
        <mesh filename="package://robotiq_2f_85_description/meshes/visual/robotiq_arg2f_85_outer_knuckle.dae" scale="0.001 0.001 0.001"/>
      </geometry>
      <material name="">
        <color rgba="0.792156862745098 0.819607843137255 0.933333333333333 1"/>
      </material>
    </visual>
    <collision>
      <origin rpy="0 0 0" xyz="0 0 0"/>
      <geometry>
        <mesh filename="package://robotiq_2f_85_description/meshes/collision/robotiq_arg2f_85_outer_knuckle.dae" scale="0.001 0.001 0.001"/>
      </geometry>
    </collision>
    <inertial>
      <mass value="0.1"/>
      <origin rpy="0 0 0" xyz="0 0 0"/>
      <inertia ixx="0.03" ixy="0.0" ixz="0.0" iyy="0.03" iyz="0.0" izz="0.03"/>
    </inertial>
  </link>
  <link name="left_outer_finger">
    <!--<inertial>
        <origin xyz="0.00030115855001899 0.0373907951953854 -0.0208027427000385" rpy="0 0 0" />
        <mass value="0.022614240507152" />
        <inertia ixx="1.52518312458174E-05" ixy="9.76583423954399E-10" ixz="-5.43838577022588E-10" iyy="6.17694243867776E-06" iyz="6.78636130740228E-06" izz="1.16494917907219E-05" />
        </inertial> -->
    <visual>
      <origin rpy="0 0 0" xyz="0 0 0"/>
      <geometry>
        <mesh filename="package://robotiq_2f_85_description/meshes/visual/robotiq_arg2f_85_outer_finger.dae" scale="0.001 0.001 0.001"/>
      </geometry>
      <material name="">
        <color rgba="0.1 0.1 0.1 1"/>
      </material>
    </visual>
    <collision>
      <origin rpy="0 0 0" xyz="0 0 0"/>
      <geometry>
        <mesh filename="package://robotiq_2f_85_description/meshes/collision/robotiq_arg2f_85_outer_finger.dae" scale="0.001 0.001 0.001"/>
      </geometry>
    </collision>
    <inertial>
      <mass value="0.1"/>
      <origin rpy="0 0 0" xyz="0 0 0"/>
      <inertia ixx="0.03" ixy="0.0" ixz="0.0" iyy="0.03" iyz="0.0" izz="0.03"/>
    </inertial>
  </link>
  <link name="left_inner_finger">
    <!--<inertial>
        <origin xyz="0.000299999999999317 0.0160078233491243 -0.0136945669206257" rpy="0 0 0" />
        <mass value="0.0104003125914103" />
        <inertia ixx="2.71909453810972E-06" ixy="1.35402465472579E-21" ixz="-7.1817349065269E-22" iyy="7.69100314106116E-07" iyz="6.74715432769696E-07" izz="2.30315190420171E-06" />
        </inertial> -->
    <visual>
      <origin rpy="0 0 0" xyz="0 0 0"/>
      <geometry>
        <mesh filename="package://robotiq_2f_85_description/meshes/visual/robotiq_arg2f_85_inner_finger.dae" scale="0.001 0.001 0.001"/>
      </geometry>
      <material name="">
        <color rgba="0.1 0.1 0.1 1"/>
      </material>
    </visual>
    <collision>
      <origin rpy="0 0 0" xyz="0 0 0"/>
      <geometry>
        <mesh filename="package://robotiq_2f_85_description/meshes/collision/robotiq_arg2f_85_inner_finger.dae" scale="0.001 0.001 0.001"/>
      </geometry>
    </collision>
    <inertial>
      <mass value="0.1"/>
      <origin rpy="0 0 0" xyz="0 0 0"/>
      <inertia ixx="0.03" ixy="0.0" ixz="0.0" iyy="0.03" iyz="0.0" izz="0.03"/>
    </inertial>
  </link>
  <link name="left_inner_finger_pad">
    <visual>
      <origin rpy="0 0 0" xyz="0 0 0"/>
      <geometry>
        <box size="0.022 0.00635 0.0375"/>
      </geometry>
      <material name="">
        <color rgba="0.9 0.9 0.9 1"/>
      </material>
    </visual>
    <collision>
      <origin rpy="0 0 0" xyz="0 0 0"/>
      <geometry>
        <box size="0.022 0.00635 0.0375"/>
      </geometry>
      <material name="">
        <color rgba="0.9 0.0 0.0 1"/>
      </material>
    </collision>
    <inertial>
      <mass value="0.1"/>
      <origin rpy="0 0 0" xyz="0 0 0"/>
      <inertia ixx="0.03" ixy="0.0" ixz="0.0" iyy="0.03" iyz="0.0" izz="0.03"/>
    </inertial>
  </link>
  <link name="left_inner_knuckle">
    <!--<inertial>
        <origin xyz="0.000123011831763771 0.0507850843201817 0.00103968640075166" rpy="0 0 0" />
       <mass value="0.0271177346495152" />
        <inertia ixx="2.61910379223783E-05" ixy="-2.43616858946494E-07" ixz="-6.37789906117123E-09" iyy="2.8270243746167E-06" iyz="-5.37200748039765E-07" izz="2.83695868220296E-05" />
        </inertial> -->
    <visual>
      <origin rpy="0 0 0" xyz="0 0 0"/>
      <geometry>
        <mesh filename="package://robotiq_2f_85_description/meshes/visual/robotiq_arg2f_85_inner_knuckle.dae" scale="0.001 0.001 0.001"/>
      </geometry>
      <material name="">
        <color rgba="0.1 0.1 0.1 1"/>
      </material>
    </visual>
    <collision>
      <origin rpy="0 0 0" xyz="0 0 0"/>
      <geometry>
        <mesh filename="package://robotiq_2f_85_description/meshes/collision/robotiq_arg2f_85_inner_knuckle.dae" scale="0.001 0.001 0.001"/>
      </geometry>
    </collision>
    <inertial>
      <mass value="0.1"/>
      <origin rpy="0 0 0" xyz="0 0 0"/>
      <inertia ixx="0.03" ixy="0.0" ixz="0.0" iyy="0.03" iyz="0.0" izz="0.03"/>
    </inertial>
  </link>
  <link name="right_outer_knuckle">
    <!--<inertial>
        <origin xyz="-0.000200000000003065 0.0199435877845359 0.0292245259211331" rpy="0 0 0" />
        <mass value="0.00853198276973456" />
        <inertia ixx="2.89328108496468E-06" ixy="-1.57935047237397E-19" ixz="-1.93980378593255E-19" iyy="1.86719750325683E-06" iyz="-1.21858577871576E-06" izz="1.21905238907251E-06" />
        </inertial> -->
    <visual>
      <origin rpy="0 0 0" xyz="0 0 0"/>
      <geometry>
        <mesh filename="package://robotiq_2f_85_description/meshes/visual/robotiq_arg2f_85_outer_knuckle.dae" scale="0.001 0.001 0.001"/>
      </geometry>
      <material name="">
        <color rgba="0.792156862745098 0.819607843137255 0.933333333333333 1"/>
      </material>
    </visual>
    <collision>
      <origin rpy="0 0 0" xyz="0 0 0"/>
      <geometry>
        <mesh filename="package://robotiq_2f_85_description/meshes/collision/robotiq_arg2f_85_outer_knuckle.dae" scale="0.001 0.001 0.001"/>
      </geometry>
    </collision>
    <inertial>
      <mass value="0.1"/>
      <origin rpy="0 0 0" xyz="0 0 0"/>
      <inertia ixx="0.03" ixy="0.0" ixz="0.0" iyy="0.03" iyz="0.0" izz="0.03"/>
    </inertial>
  </link>
  <link name="right_outer_finger">
    <!--<inertial>
        <origin xyz="0.00030115855001899 0.0373907951953854 -0.0208027427000385" rpy="0 0 0" />
        <mass value="0.022614240507152" />
        <inertia ixx="1.52518312458174E-05" ixy="9.76583423954399E-10" ixz="-5.43838577022588E-10" iyy="6.17694243867776E-06" iyz="6.78636130740228E-06" izz="1.16494917907219E-05" />
        </inertial> -->
    <visual>
      <origin rpy="0 0 0" xyz="0 0 0"/>
      <geometry>
        <mesh filename="package://robotiq_2f_85_description/meshes/visual/robotiq_arg2f_85_outer_finger.dae" scale="0.001 0.001 0.001"/>
      </geometry>
      <material name="">
        <color rgba="0.1 0.1 0.1 1"/>
      </material>
    </visual>
    <collision>
      <origin rpy="0 0 0" xyz="0 0 0"/>
      <geometry>
        <mesh filename="package://robotiq_2f_85_description/meshes/collision/robotiq_arg2f_85_outer_finger.dae" scale="0.001 0.001 0.001"/>
      </geometry>
    </collision>
    <inertial>
      <mass value="0.1"/>
      <origin rpy="0 0 0" xyz="0 0 0"/>
      <inertia ixx="0.03" ixy="0.0" ixz="0.0" iyy="0.03" iyz="0.0" izz="0.03"/>
    </inertial>
  </link>
  <link name="right_inner_finger">
    <!--<inertial>
        <origin xyz="0.000299999999999317 0.0160078233491243 -0.0136945669206257" rpy="0 0 0" />
        <mass value="0.0104003125914103" />
        <inertia ixx="2.71909453810972E-06" ixy="1.35402465472579E-21" ixz="-7.1817349065269E-22" iyy="7.69100314106116E-07" iyz="6.74715432769696E-07" izz="2.30315190420171E-06" />
        </inertial> -->
    <visual>
      <origin rpy="0 0 0" xyz="0 0 0"/>
      <geometry>
        <mesh filename="package://robotiq_2f_85_description/meshes/visual/robotiq_arg2f_85_inner_finger.dae" scale="0.001 0.001 0.001"/>
      </geometry>
      <material name="">
        <color rgba="0.1 0.1 0.1 1"/>
      </material>
    </visual>
    <collision>
      <origin rpy="0 0 0" xyz="0 0 0"/>
      <geometry>
        <mesh filename="package://robotiq_2f_85_description/meshes/collision/robotiq_arg2f_85_inner_finger.dae" scale="0.001 0.001 0.001"/>
      </geometry>
    </collision>
    <inertial>
      <mass value="0.1"/>
      <origin rpy="0 0 0" xyz="0 0 0"/>
      <inertia ixx="0.03" ixy="0.0" ixz="0.0" iyy="0.03" iyz="0.0" izz="0.03"/>
    </inertial>
  </link>
  <link name="right_inner_finger_pad">
    <visual>
      <origin rpy="0 0 0" xyz="0 0 0"/>
      <geometry>
        <box size="0.022 0.00635 0.0375"/>
      </geometry>
      <material name="">
        <color rgba="0.9 0.9 0.9 1"/>
      </material>
    </visual>
    <collision>
      <origin rpy="0 0 0" xyz="0 0 0"/>
      <geometry>
        <box size="0.022 0.00635 0.0375"/>
      </geometry>
      <material name="">
        <color rgba="0.9 0.0 0.0 1"/>
      </material>
    </collision>
    <inertial>
      <mass value="0.1"/>
      <origin rpy="0 0 0" xyz="0 0 0"/>
      <inertia ixx="0.03" ixy="0.0" ixz="0.0" iyy="0.03" iyz="0.0" izz="0.03"/>
    </inertial>
  </link>
  <link name="right_inner_knuckle">
    <!--<inertial>
        <origin xyz="0.000123011831763771 0.0507850843201817 0.00103968640075166" rpy="0 0 0" />
       <mass value="0.0271177346495152" />
        <inertia ixx="2.61910379223783E-05" ixy="-2.43616858946494E-07" ixz="-6.37789906117123E-09" iyy="2.8270243746167E-06" iyz="-5.37200748039765E-07" izz="2.83695868220296E-05" />
        </inertial> -->
    <visual>
      <origin rpy="0 0 0" xyz="0 0 0"/>
      <geometry>
        <mesh filename="package://robotiq_2f_85_description/meshes/visual/robotiq_arg2f_85_inner_knuckle.dae" scale="0.001 0.001 0.001"/>
      </geometry>
      <material name="">
        <color rgba="0.1 0.1 0.1 1"/>
      </material>
    </visual>
    <collision>
      <origin rpy="0 0 0" xyz="0 0 0"/>
      <geometry>
        <mesh filename="package://robotiq_2f_85_description/meshes/collision/robotiq_arg2f_85_inner_knuckle.dae" scale="0.001 0.001 0.001"/>
      </geometry>
    </collision>
    <inertial>
      <mass value="0.1"/>
      <origin rpy="0 0 0" xyz="0 0 0"/>
      <inertia ixx="0.03" ixy="0.0" ixz="0.0" iyy="0.03" iyz="0.0" izz="0.03"/>
    </inertial>
  </link>
  <joint name="finger_joint" type="revolute">
    <origin rpy="0 0 3.141592653589793" xyz="0 -0.0306011 0.054904"/>
    <parent link="robotiq_arg2f_base_link"/>
    <child link="left_outer_knuckle"/>
    <axis xyz="1 0 0"/>
    <limit effort="1000" lower="0" upper="0.8" velocity="2.0"/>
  </joint>
  <joint name="left_outer_finger_joint" type="fixed">
    <origin rpy="0 0 0" xyz="0 0.0315 -0.0041"/>
    <parent link="left_outer_knuckle"/>
    <child link="left_outer_finger"/>
    <axis xyz="1 0 0"/>
  </joint>
  <joint name="left_inner_knuckle_joint" type="revolute">
    <!-- <origin xyz="0 ${reflect * -0.0127} 0.06142" rpy="${pi / 2 + .725} 0 ${(reflect - 1) * pi / 2}" /> -->
    <origin rpy="0 0 3.141592653589793" xyz="0 -0.0127 0.06142"/>
    <parent link="robotiq_arg2f_base_link"/>
    <child link="left_inner_knuckle"/>
    <axis xyz="1 0 0"/>
    <limit effort="1000" lower="0" upper="0.8757" velocity="2.0"/>
    <mimic joint="finger_joint" multiplier="1" offset="0"/>
  </joint>
  <joint name="left_inner_finger_joint" type="revolute">
    <origin rpy="0 0 0" xyz="0 0.0061 0.0471"/>
    <parent link="left_outer_finger"/>
    <child link="left_inner_finger"/>
    <axis xyz="1 0 0"/>
    <limit effort="1000" lower="-0.8757" upper="0.8757" velocity="2.0"/>
    <mimic joint="finger_joint" multiplier="-1" offset="0"/>
  </joint>
  <joint name="left_inner_finger_pad_joint" type="fixed">
    <origin rpy="0 0 0" xyz="0 -0.0220203446692936 0.03242"/>
    <parent link="left_inner_finger"/>
    <child link="left_inner_finger_pad"/>
    <axis xyz="0 0 1"/>
  </joint>
  <joint name="right_outer_knuckle_joint" type="revolute">
    <origin rpy="0 0 0" xyz="0 0.0306011 0.054904"/>
    <parent link="robotiq_arg2f_base_link"/>
    <child link="right_outer_knuckle"/>
    <axis xyz="1 0 0"/>
    <limit effort="1000" lower="0" upper="0.81" velocity="2.0"/>
    <mimic joint="finger_joint" multiplier="1" offset="0"/>
  </joint>
  <joint name="right_outer_finger_joint" type="fixed">
    <origin rpy="0 0 0" xyz="0 0.0315 -0.0041"/>
    <parent link="right_outer_knuckle"/>
    <child link="right_outer_finger"/>
    <axis xyz="1 0 0"/>
  </joint>
  <joint name="right_inner_knuckle_joint" type="revolute">
    <!-- <origin xyz="0 ${reflect * -0.0127} 0.06142" rpy="${pi / 2 + .725} 0 ${(reflect - 1) * pi / 2}" /> -->
    <origin rpy="0 0 0.0" xyz="0 0.0127 0.06142"/>
    <parent link="robotiq_arg2f_base_link"/>
    <child link="right_inner_knuckle"/>
    <axis xyz="1 0 0"/>
    <limit effort="1000" lower="0" upper="0.8757" velocity="2.0"/>
    <mimic joint="finger_joint" multiplier="1" offset="0"/>
  </joint>
  <joint name="right_inner_finger_joint" type="revolute">
    <origin rpy="0 0 0" xyz="0 0.0061 0.0471"/>
    <parent link="right_outer_finger"/>
    <child link="right_inner_finger"/>
    <axis xyz="1 0 0"/>
    <limit effort="1000" lower="-0.8757" upper="0.8757" velocity="2.0"/>
    <mimic joint="finger_joint" multiplier="-1" offset="0"/>
  </joint>
  <joint name="right_inner_finger_pad_joint" type="fixed">
    <origin rpy="0 0 0" xyz="0 -0.0220203446692936 0.03242"/>
    <parent link="right_inner_finger"/>
    <child link="right_inner_finger_pad"/>
    <axis xyz="0 0 1"/>
  </joint>
  <transmission name="finger_joint_trans">
    <type>transmission_interface/SimpleTransmission</type>
    <joint name="finger_joint">
      <hardwareInterface>hardware_interface/PositionJointInterface</hardwareInterface>
    </joint>
    <actuator name="finger_joint_motor">
      <mechanicalReduction>1</mechanicalReduction>
      <hardwareInterface>hardware_interface/PositionJointInterface</hardwareInterface>
    </actuator>
  </transmission>
  <link name="coupling_link">
    <visual>
      <origin rpy="0 0 1.5707963267948966" xyz="0 0 0.007"/>
      <geometry>
        <mesh filename="package://robotiq_2f_85_description/meshes/visual/robotiq_gripper_coupling.stl" scale="0.001 0.001 0.001"/>
      </geometry>
      <material name="">
        <color rgba="0.1 0.1 0.1 1"/>
      </material>
    </visual>
    <collision>
      <origin rpy="0 0 0" xyz="0 0 0"/>
      <geometry>
        <mesh filename="package://robotiq_2f_85_description/meshes/visual/robotiq_gripper_coupling.stl" scale="0.001 0.001 0.001"/>
      </geometry>
    </collision>
    <inertial>
      <mass value="0.1"/>
      <origin rpy="0 0 0" xyz="0 0 0"/>
      <inertia ixx="0.03" ixy="0.0" ixz="0.0" iyy="0.03" iyz="0.0" izz="0.03"/>
    </inertial>
  </link>
  <joint name="coupling_joint" type="fixed">
    <origin rpy="0 0 0" xyz="0 0 0.011"/>
    <parent link="coupling_link"/>
    <child link="robotiq_arg2f_base_link"/>
  </joint>
  <joint name="abb_joint_gripper_support" type="fixed">
    <parent link="tool0"/>
    <child link="coupling_link"/>
    <origin rpy="0 0 0" xyz="0 0 -0.003"/>
  </joint>
  <!-- KR10 -->
  <transmission name="trans_left_inner_knuckle_joint">
    <type>transmission_interface/SimpleTransmission</type>
    <joint name="left_inner_knuckle_joint">
      <hardwareInterface>hardware_interface/PositionJointInterface</hardwareInterface>
    </joint>
    <actuator name="left_inner_knuckle_joint_motor">
      <hardwareInterface>hardware_interface/PositionJointInterface</hardwareInterface>
      <mechanicalReduction>1</mechanicalReduction>
    </actuator>
  </transmission>
  <transmission name="trans_left_inner_finger_joint">
    <type>transmission_interface/SimpleTransmission</type>
    <joint name="left_inner_finger_joint">
      <hardwareInterface>hardware_interface/PositionJointInterface</hardwareInterface>
    </joint>
    <actuator name="left_inner_finger_joint_motor">
      <hardwareInterface>hardware_interface/PositionJointInterface</hardwareInterface>
      <mechanicalReduction>1</mechanicalReduction>
    </actuator>
  </transmission>
  <transmission name="trans_right_outer_knuckle_joint">
    <type>transmission_interface/SimpleTransmission</type>
    <joint name="right_outer_knuckle_joint">
      <hardwareInterface>hardware_interface/PositionJointInterface</hardwareInterface>
    </joint>
    <actuator name="right_outer_knuckle_joint_motor">
      <hardwareInterface>hardware_interface/PositionJointInterface</hardwareInterface>
      <mechanicalReduction>1</mechanicalReduction>
    </actuator>
  </transmission>
  <transmission name="trans_right_inner_knuckle_joint">
    <type>transmission_interface/SimpleTransmission</type>
    <joint name="right_inner_knuckle_joint">
      <hardwareInterface>hardware_interface/PositionJointInterface</hardwareInterface>
    </joint>
    <actuator name="right_inner_knuckle_joint_motor">
      <hardwareInterface>hardware_interface/PositionJointInterface</hardwareInterface>
      <mechanicalReduction>1</mechanicalReduction>
    </actuator>
  </transmission>
  <transmission name="trans_right_inner_finger_joint">
    <type>transmission_interface/SimpleTransmission</type>
    <joint name="right_inner_finger_joint">
      <hardwareInterface>hardware_interface/PositionJointInterface</hardwareInterface>
    </joint>
    <actuator name="right_inner_finger_joint_motor">
      <hardwareInterface>hardware_interface/PositionJointInterface</hardwareInterface>
      <mechanicalReduction>1</mechanicalReduction>
    </actuator>
  </transmission>
  <gazebo>
    <!-- loading plugin: mimic joints works in gazebo now -->
    <plugin filename="libroboticsgroup_upatras_gazebo_mimic_joint_plugin.so" name="mimic_robotiq_85_1">
      <joint>finger_joint</joint>
      <mimicJoint>right_outer_knuckle_joint</mimicJoint>
      <multiplier>1.0</multiplier>
      <!--<offset>0.0</offset-->
    </plugin>
    <plugin filename="libroboticsgroup_upatras_gazebo_mimic_joint_plugin.so" name="mimic_robotiq_85_5">
      <joint>finger_joint</joint>
      <mimicJoint>left_inner_finger_joint</mimicJoint>
      <multiplier>-1.0</multiplier>
      <!--offset>0.0</offset-->
    </plugin>
    <plugin filename="libroboticsgroup_upatras_gazebo_mimic_joint_plugin.so" name="mimic_robotiq_85_4">
      <joint>finger_joint</joint>
      <mimicJoint>right_inner_finger_joint</mimicJoint>
      <multiplier>-1.0</multiplier>
      <!--offset>0.0</offset-->
    </plugin>
    <plugin filename="libroboticsgroup_upatras_gazebo_mimic_joint_plugin.so" name="mimic_robotiq_85_2">
      <joint>finger_joint</joint>
      <mimicJoint>left_inner_knuckle_joint</mimicJoint>
      <multiplier>1.0</multiplier>
      <!--<offset>0.0</offset-->
    </plugin>
    <plugin filename="libroboticsgroup_upatras_gazebo_mimic_joint_plugin.so" name="mimic_robotiq_85_3">
      <joint>finger_joint</joint>
      <mimicJoint>right_inner_knuckle_joint</mimicJoint>
      <multiplier>1.0</multiplier>
      <!--<offset>0.0</offset-->
    </plugin>
  </gazebo>
  <!-- Plugin -->
  <gazebo>
    <plugin filename="libgazebo_grasp_fix.so" name="gazebo_grasp_fix">
      <arm>
        <arm_name>abb_irb4600</arm_name>
        <palm_link>link_6</palm_link>
        <gripper_link>left_outer_knuckle</gripper_link>
        <gripper_link>right_outer_knuckle</gripper_link>
        <gripper_link>left_inner_finger</gripper_link>
        <gripper_link>right_inner_finger</gripper_link>
      </arm>
      <forces_angle_tolerance>90</forces_angle_tolerance>
      <update_rate>4</update_rate>
      <grip_count_threshold>4</grip_count_threshold>
      <max_grip_count>8</max_grip_count>
      <release_tolerance>0.005</release_tolerance>
      <disable_collisions_on_attach>false</disable_collisions_on_attach>
      <contact_topic>__default_topic__</contact_topic>
    </plugin>
  </gazebo>
</robot>

