<?xml version="1.0"?>
<robot xmlns:xacro="http://ros.org/wiki/xacro" name="pallet_gripper">
  <xacro:macro name="pallet_gripper" params="prefix parent *origin">
    <joint name="${prefix}gripper_base_joint" type="fixed">
      <xacro:insert_block name="origin"/>
      <parent link="${parent}"/>
      <child link="${prefix}gripper_base_link"/>
    </joint>

    <link name="${prefix}gripper_base_link">
      <visual>
        <geometry>
          <box size="0.1 0.1 0.1"/>
        </geometry>
        <material name="gray">
          <color rgba="0.5 0.5 0.5 1"/>
        </material>
      </visual>
      <collision>
        <geometry>
          <box size="0.1 0.1 0.1"/>
        </geometry>
      </collision>
      <inertial>
        <mass value="0.5"/>
        <origin xyz="0 0 0" rpy="0 0 0"/>
        <inertia ixx="0.1" iyy="0.1" izz="0.1" ixy="0.0" ixz="0.0" iyz="0.0"/>
      </inertial>
    </link>

    <joint name="${prefix}left_finger_joint" type="prismatic">
      <parent link="${prefix}gripper_base_link"/>
      <child link="${prefix}left_finger_link"/>
      <origin xyz="0 0.05 0" rpy="0 0 0"/>
      <axis xyz="0 1 0"/>
      <limit lower="0" upper="0.4" effort="1000" velocity="0.5"/>
    </joint>

    <link name="${prefix}left_finger_link">
      <visual>
        <geometry>
          <box size="0.1 0.02 0.3"/>
        </geometry>
        <material name="blue">
          <color rgba="0 0 1 1"/>
        </material>
      </visual>
      <collision>
        <geometry>
          <box size="0.1 0.02 0.3"/>
        </geometry>
      </collision>
      <inertial>
        <mass value="0.3"/>
        <origin xyz="0 0 0" rpy="0 0 0"/>
        <inertia ixx="0.1" iyy="0.1" izz="0.1" ixy="0.0" ixz="0.0" iyz="0.0"/>
      </inertial>
    </link>

    <joint name="${prefix}right_finger_joint" type="prismatic">
      <parent link="${prefix}gripper_base_link"/>
      <child link="${prefix}right_finger_link"/>
      <origin xyz="0 -0.05 0" rpy="0 0 0"/>
      <axis xyz="0 -1 0"/>
      <limit lower="0" upper="0.4" effort="1000" velocity="0.5"/>
      <mimic joint="${prefix}left_finger_joint"/>
    </joint>

    <link name="${prefix}right_finger_link">
      <visual>
        <geometry>
          <box size="0.1 0.02 0.3"/>
        </geometry>
        <material name="blue">
          <color rgba="0 0 1 1"/>
        </material>
      </visual>
      <collision>
        <geometry>
          <box size="0.1 0.02 0.3"/>
        </geometry>
      </collision>
      <inertial>
        <mass value="0.3"/>
        <origin xyz="0 0 0" rpy="0 0 0"/>
        <inertia ixx="0.1" iyy="0.1" izz="0.1" ixy="0.0" ixz="0.0" iyz="0.0"/>
      </inertial>
    </link>

    <gazebo>
      <plugin name="gazebo_ros_control" filename="libgazebo_ros_control.so">
        <robotNamespace>/${prefix}</robotNamespace>
      </plugin>
    </gazebo>
  </xacro:macro>
</robot>